<?xml version="1.0"?>
<!--
  Coffee Shop Butler Robot URDF (Xacro)
  =======================================
  Based on TurtleBot3 Burger with:
    • LiDAR (Hokuyo-style) for Nav2 AMCL localisation
    • diff_drive Gazebo plugin
    • IMU plugin
    • Laser scan plugin

  If you have turtlebot3_description installed you can replace this with:
    <xacro:include filename="$(find turtlebot3_description)/urdf/turtlebot3_burger.urdf.xacro"/>
  Otherwise this self-contained description is used.
-->
<robot name="coffee_shop_robot" xmlns:xacro="http://www.ros.org/wiki/xacro">

  <!-- ── Parameters ─────────────────────────────────────────────────── -->
  <xacro:property name="base_mass"       value="1.0"/>
  <xacro:property name="base_radius"     value="0.105"/>
  <xacro:property name="base_height"     value="0.065"/>

  <xacro:property name="wheel_mass"      value="0.1"/>
  <xacro:property name="wheel_radius"    value="0.033"/>
  <xacro:property name="wheel_width"     value="0.018"/>
  <xacro:property name="wheel_base"      value="0.16"/>   <!-- half the track width -->

  <xacro:property name="caster_radius"   value="0.017"/>

  <!-- ── Materials ──────────────────────────────────────────────────── -->
  <material name="dark_grey">
    <color rgba="0.2 0.2 0.2 1"/>
  </material>
  <material name="light_grey">
    <color rgba="0.7 0.7 0.7 1"/>
  </material>
  <material name="orange">
    <color rgba="1.0 0.4 0.0 1"/>
  </material>

  <!-- ── Base link ──────────────────────────────────────────────────── -->
  <link name="base_footprint"/>

  <joint name="base_joint" type="fixed">
    <parent link="base_footprint"/>
    <child  link="base_link"/>
    <origin xyz="0 0 0.010" rpy="0 0 0"/>
  </joint>

  <link name="base_link">
    <visual>
      <origin xyz="0 0 ${base_height/2}" rpy="0 0 0"/>
      <geometry><cylinder radius="${base_radius}" length="${base_height}"/></geometry>
      <material name="dark_grey"/>
    </visual>
    <collision>
      <origin xyz="0 0 ${base_height/2}" rpy="0 0 0"/>
      <geometry><cylinder radius="${base_radius}" length="${base_height}"/></geometry>
    </collision>
    <inertial>
      <mass value="${base_mass}"/>
      <inertia ixx="0.0077" iyy="0.0077" izz="0.0137" ixy="0" ixz="0" iyz="0"/>
    </inertial>
  </link>

  <!-- ── Wheels ─────────────────────────────────────────────────────── -->
  <xacro:macro name="wheel" params="name x_reflect">
    <link name="${name}_wheel_link">
      <visual>
        <origin xyz="0 0 0" rpy="${pi/2} 0 0"/>
        <geometry><cylinder radius="${wheel_radius}" length="${wheel_width}"/></geometry>
        <material name="light_grey"/>
      </visual>
      <collision>
        <origin xyz="0 0 0" rpy="${pi/2} 0 0"/>
        <geometry><cylinder radius="${wheel_radius}" length="${wheel_width}"/></geometry>
      </collision>
      <inertial>
        <mass value="${wheel_mass}"/>
        <inertia ixx="0.00003" iyy="0.00003" izz="0.00006" ixy="0" ixz="0" iyz="0"/>
      </inertial>
    </link>
    <joint name="${name}_wheel_joint" type="continuous">
      <parent link="base_link"/>
      <child  link="${name}_wheel_link"/>
      <origin xyz="0 ${x_reflect * wheel_base} ${wheel_radius}" rpy="0 0 0"/>
      <axis xyz="0 1 0"/>
    </joint>
  </xacro:macro>

  <xacro:wheel name="left"  x_reflect="1"/>
  <xacro:wheel name="right" x_reflect="-1"/>

  <!-- ── Caster ─────────────────────────────────────────────────────── -->
  <link name="caster_link">
    <visual>
      <geometry><sphere radius="${caster_radius}"/></geometry>
      <material name="light_grey"/>
    </visual>
    <collision>
      <geometry><sphere radius="${caster_radius}"/></geometry>
    </collision>
    <inertial>
      <mass value="0.01"/>
      <inertia ixx="0.000001" iyy="0.000001" izz="0.000001" ixy="0" ixz="0" iyz="0"/>
    </inertial>
  </link>
  <joint name="caster_joint" type="fixed">
    <parent link="base_link"/>
    <child  link="caster_link"/>
    <origin xyz="-0.081 0 ${caster_radius}" rpy="0 0 0"/>
  </joint>

  <!-- ── LiDAR ──────────────────────────────────────────────────────── -->
  <link name="base_scan">
    <visual>
      <origin xyz="0 0 0" rpy="0 0 0"/>
      <geometry><cylinder radius="0.038" length="0.042"/></geometry>
      <material name="orange"/>
    </visual>
    <collision>
      <origin xyz="0 0 0" rpy="0 0 0"/>
      <geometry><cylinder radius="0.038" length="0.042"/></geometry>
    </collision>
    <inertial>
      <mass value="0.125"/>
      <inertia ixx="0.000000065" iyy="0.000000065" izz="0.000000101" ixy="0" ixz="0" iyz="0"/>
    </inertial>
  </link>
  <joint name="scan_joint" type="fixed">
    <parent link="base_link"/>
    <child  link="base_scan"/>
    <origin xyz="-0.032 0 0.172" rpy="0 0 0"/>
  </joint>

  <!-- ── IMU ────────────────────────────────────────────────────────── -->
  <link name="imu_link">
    <inertial>
      <mass value="0.001"/>
      <inertia ixx="0.0000001" iyy="0.0000001" izz="0.0000001" ixy="0" ixz="0" iyz="0"/>
    </inertial>
  </link>
  <joint name="imu_joint" type="fixed">
    <parent link="base_link"/>
    <child  link="imu_link"/>
    <origin xyz="-0.032 0 0.068" rpy="0 0 0"/>
  </joint>

  <!-- ── Gazebo plugins ─────────────────────────────────────────────── -->
  <!-- Differential drive controller -->
  <gazebo>
    <plugin name="differential_drive_controller"
            filename="libgazebo_ros_diff_drive.so">
      <ros>
        <remapping>cmd_vel:=cmd_vel</remapping>
        <remapping>odom:=odom</remapping>
      </ros>
      <left_joint>left_wheel_joint</left_joint>
      <right_joint>right_wheel_joint</right_joint>
      <wheel_separation>${wheel_base * 2}</wheel_separation>
      <wheel_diameter>${wheel_radius * 2}</wheel_diameter>
      <max_wheel_torque>20</max_wheel_torque>
      <max_wheel_acceleration>1.0</max_wheel_acceleration>
      <publish_odom>true</publish_odom>
      <publish_odom_tf>true</publish_odom_tf>
      <publish_wheel_tf>true</publish_wheel_tf>
      <odometry_frame>odom</odometry_frame>
      <robot_base_frame>base_footprint</robot_base_frame>
    </plugin>
  </gazebo>

  <!-- LiDAR plugin -->
  <gazebo reference="base_scan">
    <sensor type="ray" name="lds_lfcd_sensor">
      <pose>0 0 0 0 0 0</pose>
      <visualize>false</visualize>
      <update_rate>5</update_rate>
      <ray>
        <scan>
          <horizontal>
            <samples>360</samples>
            <resolution>1</resolution>
            <min_angle>0.0</min_angle>
            <max_angle>6.28319</max_angle>
          </horizontal>
        </scan>
        <range>
          <min>0.120</min>
          <max>3.5</max>
          <resolution>0.015</resolution>
        </range>
        <noise>
          <type>gaussian</type>
          <mean>0.0</mean>
          <stddev>0.01</stddev>
        </noise>
      </ray>
      <plugin name="gazebo_ros_lds_lfcd_controller"
              filename="libgazebo_ros_laser.so">
        <ros>
          <remapping>~/out:=scan</remapping>
        </ros>
        <output_type>sensor_msgs/LaserScan</output_type>
        <frame_name>base_scan</frame_name>
      </plugin>
    </sensor>
  </gazebo>

  <!-- IMU plugin -->
  <gazebo reference="imu_link">
    <sensor name="imu_sensor" type="imu">
      <always_on>true</always_on>
      <update_rate>200</update_rate>
      <visualize>true</visualize>
      <plugin filename="libgazebo_ros_imu_sensor.so" name="imu_plugin">
        <ros>
          <remapping>~/out:=imu</remapping>
        </ros>
        <initial_orientation_as_reference>false</initial_orientation_as_reference>
      </plugin>
      <pose>0 0 0 0 0 0</pose>
    </sensor>
  </gazebo>

</robot>
